Workbook

Sheet 20251125 Ranked by Tower, MM
A1: ItemID | B1: Item | D1: Mastered | E1: Grand Mastered | F1: Mega Mastered | G1: King's Rating April 2023* | H1: ClientCoin Rating 2024 | I1: Tower Req | J1: Score* | L1: Fish? | M1: Craft? | N1: Explore? | O1: Farm? | P1: Cook? | Q1: Event? | S1: Document is sorted by Tower Req then MM
A2: 21 | B2: Board | C2: =CONCATENATE("((",B2,"))") -> ((Board)) | D2: 87800 | E2: 62478 | F2: 30235 | G2: =VLOOKUP(B2,'Kings Ratings'!$A$2:$B$1000,2,false) -> 1 | H2: =if(G2=11,13,13-ROUNDDOWN(log(J2,4),0)) -> -1 | I2: =vlookup(A2,'202405 MM (Do Not Delete)'!$A$1:$G$1000,7,false) -> 201 | J2: =10000*F2+10*E2+D2 -> 303062580 | L2: =IFERROR(__xludf.DUMMYFUNCTION("if(REGEXMATCH(vlookup(B2,'Kings Ratings'!$A$2:$C$1000,3,false),""Fishing""),""Yes"","""")"),"") | M2: =IFERROR(__xludf.DUMMYFUNCTION("if(REGEXMATCH(vlookup(B2,'Kings Ratings'!$A$2:$C$1000,3,false),""Crafting""),""Yes"","""")"),"Yes") -> Yes | N2: =IFERROR(__xludf.DUMMYFUNCTION("if(REGEXMATCH(vlookup(B2,'Kings Ratings'!$A$2:$C$1000,3,false),""Exploring""),""Yes"","""")"),"") | O2: =IFERROR(__xludf.DUMMYFUNCTION("if(REGEXMATCH(vlookup(B2,'Kings Ratings'!$A$2:$C$1000,3,false),""Farming""),""Yes"","""")"),"") | P2: =IFERROR(__xludf.DUMMYFUNCTION("if(REGEXMATCH(vlookup(B2,'Kings Ratings'!$A$2:$C$1000,3,false),""Cooking""),""Yes"","""")"),"") | Q2: =IFERROR(__xludf.DUMMYFUNCTION("if(REGEXMATCH(vlookup(B2,'Kings Ratings'!$A$2:$C$1000,3,false),""Event""),""Yes"","""")"),"")
A3: 43 | B3: Mushroom | C3: =CONCATENATE("((",B3,"))") -> ((Mushroom)) | D3: 64993 | E3: 37722 | F3: 15495 | G3: =VLOOKUP(B3,'Kings Ratings'!$A$2:$B$1000,2,false) -> 1 | H3: =if(G3=11,13,13-ROUNDDOWN(log(J3,4),0)) -> 0 | I3: =vlookup(A3,'202405 MM (Do Not Delete)'!$A$1:$G$1000,7,false) -> 208 | J3: =10000*F3+10*E3+D3 -> 155392213 | L3: =IFERROR(__xludf.DUMMYFUNCTION("if(REGEXMATCH(vlookup(B3,'Kings Ratings'!$A$2:$C$1000,3,false),""Fishing""),""Yes"","""")"),"") | M3: =IFERROR(__xludf.DUMMYFUNCTION("if(REGEXMATCH(vlookup(B3,'Kings Ratings'!$A$2:$C$1000,3,false),""Crafting""),""Yes"","""")"),"") | N3: =IFERROR(__xludf.DUMMYFUNCTION("if(REGEXMATCH(vlookup(B3,'Kings Ratings'!$A$2:$C$1000,3,false),""Exploring""),""Yes"","""")"),"Yes") -> Yes | O3: =IFERROR(__xludf.DUMMYFUNCTION("if(REGEXMATCH(vlookup(B3,'Kings Ratings'!$A$2:$C$1000,3,false),""Farming""),""Yes"","""")"),"") | P3: =IFERROR(__xludf.DUMMYFUNCTION("if(REGEXMATCH(vlookup(B3,'Kings Ratings'!$A$2:$C$1000,3,false),""Cooking""),""Yes"","""")"),"") | Q3: =IFERROR(__xludf.DUMMYFUNCTION("if(REGEXMATCH(vlookup(B3,'Kings Ratings'!$A$2:$C$1000,3,false),""Event""),""Yes"","""")"),"") | S3: Score showcases difficulty
A4: 95 | B4: Iron Ring | C4: =CONCATENATE("((",B4,"))") -> ((Iron Ring)) | D4: 61712 | E4: 39090 | F4: 16767 | G4: =VLOOKUP(B4,'Kings Ratings'!$A$2:$B$1000,2,false) -> 1 | H4: =if(G4=11,13,13-ROUNDDOWN(log(J4,4),0)) -> 0 | I4: =vlookup(A4,'202405 MM (Do Not Delete)'!$A$1:$G$1000,7,false) -> 203 | J4: =10000*F4+10*E4+D4 -> 168122612 | L4: =IFERROR(__xludf.DUMMYFUNCTION("if(REGEXMATCH(vlookup(B4,'Kings Ratings'!$A$2:$C$1000,3,false),""Fishing""),""Yes"","""")"),"") | M4: =IFERROR(__xludf.DUMMYFUNCTION("if(REGEXMATCH(vlookup(B4,'Kings Ratings'!$A$2:$C$1000,3,false),""Crafting""),""Yes"","""")"),"Yes") -> Yes | N4: =IFERROR(__xludf.DUMMYFUNCTION("if(REGEXMATCH(vlookup(B4,'Kings Ratings'!$A$2:$C$1000,3,false),""Exploring""),""Yes"","""")"),"") | O4: =IFERROR(__xludf.DUMMYFUNCTION("if(REGEXMATCH(vlookup(B4,'Kings Ratings'!$A$2:$C$1000,3,false),""Farming""),""Yes"","""")"),"") | P4: =IFERROR(__xludf.DUMMYFUNCTION("if(REGEXMATCH(vlookup(B4,'Kings Ratings'!$A$2:$C$1000,3,false),""Cooking""),""Yes"","""")"),"") | Q4: =IFERROR(__xludf.DUMMYFUNCTION("if(REGEXMATCH(vlookup(B4,'Kings Ratings'!$A$2:$C$1000,3,false),""Event""),""Yes"","""")"),"") | S4: Score is 10000*MM + 10*GM + M
A5: 76 | B5: Unpolished Shimmer Stone | C5: =CONCATENATE("((",B5,"))") -> ((Unpolished Shimmer Stone)) | D5: 60495 | E5: 31241 | F5: 12251 | G5: =VLOOKUP(B5,'Kings Ratings'!$A$2:$B$1000,2,false) -> 1 | H5: =if(G5=11,13,13-ROUNDDOWN(log(J5,4),0)) -> 0 | I5: =vlookup(A5,'202405 MM (Do Not Delete)'!$A$1:$G$1000,7,false) -> 259 | J5: =10000*F5+10*E5+D5 -> 122882905 | L5: =IFERROR(__xludf.DUMMYFUNCTION("if(REGEXMATCH(vlookup(B5,'Kings Ratings'!$A$2:$C$1000,3,false),""Fishing""),""Yes"","""")"),"") | M5: =IFERROR(__xludf.DUMMYFUNCTION("if(REGEXMATCH(vlookup(B5,'Kings Ratings'!$A$2:$C$1000,3,false),""Crafting""),""Yes"","""")"),"") | N5: =IFERROR(__xludf.DUMMYFUNCTION("if(REGEXMATCH(vlookup(B5,'Kings Ratings'!$A$2:$C$1000,3,false),""Exploring""),""Yes"","""")"),"Yes") -> Yes | O5: =IFERROR(__xludf.DUMMYFUNCTION("if(REGEXMATCH(vlookup(B5,'Kings Ratings'!$A$2:$C$1000,3,false),""Farming""),""Yes"","""")"),"") | P5: =IFERROR(__xludf.DUMMYFUNCTION("if(REGEXMATCH(vlookup(B5,'Kings Ratings'!$A$2:$C$1000,3,false),""Cooking""),""Yes"","""")"),"") | Q5: =IFERROR(__xludf.DUMMYFUNCTION("if(REGEXMATCH(vlookup(B5,'Kings Ratings'!$A$2:$C$1000,3,false),""Event""),""Yes"","""")"),"") | S5: The lower the score, the harder
A6: 163 | B6: Twine | C6: =CONCATENATE("((",B6,"))") -> ((Twine)) | D6: 59720 | E6: 40498 | F6: 20388 | G6: =VLOOKUP(B6,'Kings Ratings'!$A$2:$B$1000,2,false) -> 1 | H6: =if(G6=11,13,13-ROUNDDOWN(log(J6,4),0)) -> 0 | I6: =vlookup(A6,'202405 MM (Do Not Delete)'!$A$1:$G$1000,7,false) -> 202 | J6: =10000*F6+10*E6+D6 -> 204344700 | L6: =IFERROR(__xludf.DUMMYFUNCTION("if(REGEXMATCH(vlookup(B6,'Kings Ratings'!$A$2:$C$1000,3,false),""Fishing""),""x"","""")"),"") | M6: =IFERROR(__xludf.DUMMYFUNCTION("if(REGEXMATCH(vlookup(B6,'Kings Ratings'!$A$2:$C$1000,3,false),""Crafting""),""Yes"","""")"),"Yes") -> Yes | N6: =IFERROR(__xludf.DUMMYFUNCTION("if(REGEXMATCH(vlookup(B6,'Kings Ratings'!$A$2:$C$1000,3,false),""Exploring""),""Yes"","""")"),"") | O6: =IFERROR(__xludf.DUMMYFUNCTION("if(REGEXMATCH(vlookup(B6,'Kings Ratings'!$A$2:$C$1000,3,false),""Farming""),""Yes"","""")"),"") | P6: =IFERROR(__xludf.DUMMYFUNCTION("if(REGEXMATCH(vlookup(B6,'Kings Ratings'!$A$2:$C$1000,3,false),""Cooking""),""Yes"","""")"),"") | Q6: =IFERROR(__xludf.DUMMYFUNCTION("if(REGEXMATCH(vlookup(B6,'Kings Ratings'!$A$2:$C$1000,3,false),""Event""),""Yes"","""")"),"") | S6: This is as based on how other people have gone after
A7: 78 | B7: Glass Orb | C7: =CONCATENATE("((",B7,"))") -> ((Glass Orb)) | D7: 58571 | E7: 28809 | F7: 11011 | G7: =VLOOKUP(B7,'Kings Ratings'!$A$2:$B$1000,2,false) -> 1 | H7: =if(G7=11,13,13-ROUNDDOWN(log(J7,4),0)) -> 0 | I7: =vlookup(A7,'202405 MM (Do Not Delete)'!$A$1:$G$1000,7,false) -> 265 | J7: =10000*F7+10*E7+D7 -> 110456661 | L7: =IFERROR(__xludf.DUMMYFUNCTION("if(REGEXMATCH(vlookup(B7,'Kings Ratings'!$A$2:$C$1000,3,false),""Fishing""),""Yes"","""")"),"") | M7: =IFERROR(__xludf.DUMMYFUNCTION("if(REGEXMATCH(vlookup(B7,'Kings Ratings'!$A$2:$C$1000,3,false),""Crafting""),""Yes"","""")"),"Yes") -> Yes | N7: =IFERROR(__xludf.DUMMYFUNCTION("if(REGEXMATCH(vlookup(B7,'Kings Ratings'!$A$2:$C$1000,3,false),""Exploring""),""Yes"","""")"),"") | O7: =IFERROR(__xludf.DUMMYFUNCTION("if(REGEXMATCH(vlookup(B7,'Kings Ratings'!$A$2:$C$1000,3,false),""Farming""),""Yes"","""")"),"") | P7: =IFERROR(__xludf.DUMMYFUNCTION("if(REGEXMATCH(vlookup(B7,'Kings Ratings'!$A$2:$C$1000,3,false),""Cooking""),""Yes"","""")"),"") | Q7: =IFERROR(__xludf.DUMMYFUNCTION("if(REGEXMATCH(vlookup(B7,'Kings Ratings'!$A$2:$C$1000,3,false),""Event""),""Yes"","""")"),"")
A8: 139 | B8: Skipjack | C8: =CONCATENATE("((",B8,"))") -> ((Skipjack)) | D8: 56454 | E8: 30475 | F8: 15776 | G8: =VLOOKUP(B8,'Kings Ratings'!$A$2:$B$1000,2,false) -> 1 | H8: =if(G8=11,13,13-ROUNDDOWN(log(J8,4),0)) -> 0 | I8: =vlookup(A8,'202405 MM (Do Not Delete)'!$A$1:$G$1000,7,false) -> 204 | J8: =10000*F8+10*E8+D8 -> 158121204 | L8: =IFERROR(__xludf.DUMMYFUNCTION("if(REGEXMATCH(vlookup(B8,'Kings Ratings'!$A$2:$C$1000,3,false),""Fishing""),""Yes"","""")"),"Yes") -> Yes | M8: =IFERROR(__xludf.DUMMYFUNCTION("if(REGEXMATCH(vlookup(B8,'Kings Ratings'!$A$2:$C$1000,3,false),""Crafting""),""Yes"","""")"),"") | N8: =IFERROR(__xludf.DUMMYFUNCTION("if(REGEXMATCH(vlookup(B8,'Kings Ratings'!$A$2:$C$1000,3,false),""Exploring""),""Yes"","""")"),"") | O8: =IFERROR(__xludf.DUMMYFUNCTION("if(REGEXMATCH(vlookup(B8,'Kings Ratings'!$A$2:$C$1000,3,false),""Farming""),""Yes"","""")"),"") | P8: =IFERROR(__xludf.DUMMYFUNCTION("if(REGEXMATCH(vlookup(B8,'Kings Ratings'!$A$2:$C$1000,3,false),""Cooking""),""Yes"","""")"),"") | Q8: =IFERROR(__xludf.DUMMYFUNCTION("if(REGEXMATCH(vlookup(B8,'Kings Ratings'!$A$2:$C$1000,3,false),""Event""),""Yes"","""")"),"") | S8: Kings Rating is GM Focused
A9: 17 | B9: Drum | C9: =CONCATENATE("((",B9,"))") -> ((Drum)) | D9: 54150 | E9: 26728 | F9: 13381 | G9: =VLOOKUP(B9,'Kings Ratings'!$A$2:$B$1000,2,false) -> 1 | H9: =if(G9=11,13,13-ROUNDDOWN(log(J9,4),0)) -> 0 | I9: =vlookup(A9,'202405 MM (Do Not Delete)'!$A$1:$G$1000,7,false) -> 219 | J9: =10000*F9+10*E9+D9 -> 134131430 | L9: =IFERROR(__xludf.DUMMYFUNCTION("if(REGEXMATCH(vlookup(B9,'Kings Ratings'!$A$2:$C$1000,3,false),""Fishing""),""Yes"","""")"),"Yes") -> Yes | M9: =IFERROR(__xludf.DUMMYFUNCTION("if(REGEXMATCH(vlookup(B9,'Kings Ratings'!$A$2:$C$1000,3,false),""Crafting""),""Yes"","""")"),"") | N9: =IFERROR(__xludf.DUMMYFUNCTION("if(REGEXMATCH(vlookup(B9,'Kings Ratings'!$A$2:$C$1000,3,false),""Exploring""),""Yes"","""")"),"") | O9: =IFERROR(__xludf.DUMMYFUNCTION("if(REGEXMATCH(vlookup(B9,'Kings Ratings'!$A$2:$C$1000,3,false),""Farming""),""Yes"","""")"),"") | P9: =IFERROR(__xludf.DUMMYFUNCTION("if(REGEXMATCH(vlookup(B9,'Kings Ratings'!$A$2:$C$1000,3,false),""Cooking""),""Yes"","""")"),"") | Q9: =IFERROR(__xludf.DUMMYFUNCTION("if(REGEXMATCH(vlookup(B9,'Kings Ratings'!$A$2:$C$1000,3,false),""Event""),""Yes"","""")"),"") | S9: ClientCoin Rating is MM Focused
A10: 36 | B10: Wooden Plank | C10: =CONCATENATE("((",B10,"))") -> ((Wooden Plank)) | D10: 54015 | E10: 26311 | F10: 10335 | G10: =VLOOKUP(B10,'Kings Ratings'!$A$2:$B$1000,2,false) -> 1 | H10: =if(G10=11,13,13-ROUNDDOWN(log(J10,4),0)) -> 0 | I10: =vlookup(A10,'202405 MM (Do Not Delete)'!$A$1:$G$1000,7,false) -> 267 | J10: =10000*F10+10*E10+D10 -> 103667125 | L10: =IFERROR(__xludf.DUMMYFUNCTION("if(REGEXMATCH(vlookup(B10,'Kings Ratings'!$A$2:$C$1000,3,false),""Fishing""),""Yes"","""")"),"") | M10: =IFERROR(__xludf.DUMMYFUNCTION("if(REGEXMATCH(vlookup(B10,'Kings Ratings'!$A$2:$C$1000,3,false),""Crafting""),""Yes"","""")"),"Yes") -> Yes | N10: =IFERROR(__xludf.DUMMYFUNCTION("if(REGEXMATCH(vlookup(B10,'Kings Ratings'!$A$2:$C$1000,3,false),""Exploring""),""Yes"","""")"),"") | O10: =IFERROR(__xludf.DUMMYFUNCTION("if(REGEXMATCH(vlookup(B10,'Kings Ratings'!$A$2:$C$1000,3,false),""Farming""),""Yes"","""")"),"") | P10: =IFERROR(__xludf.DUMMYFUNCTION("if(REGEXMATCH(vlookup(B10,'Kings Ratings'!$A$2:$C$1000,3,false),""Cooking""),""Yes"","""")"),"") | Q10: =IFERROR(__xludf.DUMMYFUNCTION("if(REGEXMATCH(vlookup(B10,'Kings Ratings'!$A$2:$C$1000,3,false),""Event""),""Yes"","""")"),"")
A11: 117 | B11: Glass Bottle | C11: =CONCATENATE("((",B11,"))") -> ((Glass Bottle)) | D11: 53956 | E11: 27811 | F11: 10067 | G11: =VLOOKUP(B11,'Kings Ratings'!$A$2:$B$1000,2,false) -> 1 | H11: =if(G11=11,13,13-ROUNDDOWN(log(J11,4),0)) -> 0 | I11: =vlookup(A11,'202405 MM (Do Not Delete)'!$A$1:$G$1000,7,false) -> 269 | J11: =10000*F11+10*E11+D11 -> 101002066 | L11: =IFERROR(__xludf.DUMMYFUNCTION("if(REGEXMATCH(vlookup(B11,'Kings Ratings'!$A$2:$C$1000,3,false),""Fishing""),""Yes"","""")"),"") | M11: =IFERROR(__xludf.DUMMYFUNCTION("if(REGEXMATCH(vlookup(B11,'Kings Ratings'!$A$2:$C$1000,3,false),""Crafting""),""Yes"","""")"),"Yes") -> Yes | N11: =IFERROR(__xludf.DUMMYFUNCTION("if(REGEXMATCH(vlookup(B11,'Kings Ratings'!$A$2:$C$1000,3,false),""Exploring""),""Yes"","""")"),"") | O11: =IFERROR(__xludf.DUMMYFUNCTION("if(REGEXMATCH(vlookup(B11,'Kings Ratings'!$A$2:$C$1000,3,false),""Farming""),""Yes"","""")"),"") | P11: =IFERROR(__xludf.DUMMYFUNCTION("if(REGEXMATCH(vlookup(B11,'Kings Ratings'!$A$2:$C$1000,3,false),""Cooking""),""Yes"","""")"),"") | Q11: =IFERROR(__xludf.DUMMYFUNCTION("if(REGEXMATCH(vlookup(B11,'Kings Ratings'!$A$2:$C$1000,3,false),""Event""),""Yes"","""")"),"")
A12: 24 | B12: Yellow Perch | C12: =CONCATENATE("((",B12,"))") -> ((Yellow Perch)) | D12: 52952 | E12: 26633 | F12: 13370 | G12: =VLOOKUP(B12,'Kings Ratings'!$A$2:$B$1000,2,false) -> 1 | H12: =if(G12=11,13,13-ROUNDDOWN(log(J12,4),0)) -> 0 | I12: =vlookup(A12,'202405 MM (Do Not Delete)'!$A$1:$G$1000,7,false) -> 261 | J12: =10000*F12+10*E12+D12 -> 134019282 | L12: =IFERROR(__xludf.DUMMYFUNCTION("if(REGEXMATCH(vlookup(B12,'Kings Ratings'!$A$2:$C$1000,3,false),""Fishing""),""Yes"","""")"),"Yes") -> Yes | M12: =IFERROR(__xludf.DUMMYFUNCTION("if(REGEXMATCH(vlookup(B12,'Kings Ratings'!$A$2:$C$1000,3,false),""Crafting""),""Yes"","""")"),"") | N12: =IFERROR(__xludf.DUMMYFUNCTION("if(REGEXMATCH(vlookup(B12,'Kings Ratings'!$A$2:$C$1000,3,false),""Exploring""),""Yes"","""")"),"") | O12: =IFERROR(__xludf.DUMMYFUNCTION("if(REGEXMATCH(vlookup(B12,'Kings Ratings'!$A$2:$C$1000,3,false),""Farming""),""Yes"","""")"),"") | P12: =IFERROR(__xludf.DUMMYFUNCTION("if(REGEXMATCH(vlookup(B12,'Kings Ratings'!$A$2:$C$1000,3,false),""Cooking""),""Yes"","""")"),"") | Q12: =IFERROR(__xludf.DUMMYFUNCTION("if(REGEXMATCH(vlookup(B12,'Kings Ratings'!$A$2:$C$1000,3,false),""Event""),""Yes"","""")"),"")
A13: 231 | B13: Torch Fish | C13: =CONCATENATE("((",B13,"))") -> ((Torch Fish)) | D13: 51290 | E13: 28756 | F13: 14430 | G13: =VLOOKUP(B13,'Kings Ratings'!$A$2:$B$1000,2,false) -> 1 | H13: =if(G13=11,13,13-ROUNDDOWN(log(J13,4),0)) -> 0 | I13: =vlookup(A13,'202405 MM (Do Not Delete)'!$A$1:$G$1000,7,false) -> 215 | J13: =10000*F13+10*E13+D13 -> 144638850 | L13: =IFERROR(__xludf.DUMMYFUNCTION("if(REGEXMATCH(vlookup(B13,'Kings Ratings'!$A$2:$C$1000,3,false),""Fishing""),""Yes"","""")"),"Yes") -> Yes | M13: =IFERROR(__xludf.DUMMYFUNCTION("if(REGEXMATCH(vlookup(B13,'Kings Ratings'!$A$2:$C$1000,3,false),""Crafting""),""Yes"","""")"),"") | N13: =IFERROR(__xludf.DUMMYFUNCTION("if(REGEXMATCH(vlookup(B13,'Kings Ratings'!$A$2:$C$1000,3,false),""Exploring""),""Yes"","""")"),"") | O13: =IFERROR(__xludf.DUMMYFUNCTION("if(REGEXMATCH(vlookup(B13,'Kings Ratings'!$A$2:$C$1000,3,false),""Farming""),""Yes"","""")"),"") | P13: =IFERROR(__xludf.DUMMYFUNCTION("if(REGEXMATCH(vlookup(B13,'Kings Ratings'!$A$2:$C$1000,3,false),""Cooking""),""Yes"","""")"),"") | Q13: =IFERROR(__xludf.DUMMYFUNCTION("if(REGEXMATCH(vlookup(B13,'Kings Ratings'!$A$2:$C$1000,3,false),""Event""),""Yes"","""")"),"")
A14: 75 | B14: Mushroom Paste | C14: =CONCATENATE("((",B14,"))") -> ((Mushroom Paste)) | D14: 48836 | E14: 24253 | F14: 9654 | G14: =VLOOKUP(B14,'Kings Ratings'!$A$2:$B$1000,2,false) -> 1 | H14: =if(G14=11,13,13-ROUNDDOWN(log(J14,4),0)) -> 0 | I14: =vlookup(A14,'202405 MM (Do Not Delete)'!$A$1:$G$1000,7,false) -> 220 | J14: =10000*F14+10*E14+D14 -> 96831366 | L14: =IFERROR(__xludf.DUMMYFUNCTION("if(REGEXMATCH(vlookup(B14,'Kings Ratings'!$A$2:$C$1000,3,false),""Fishing""),""Yes"","""")"),"") | M14: =IFERROR(__xludf.DUMMYFUNCTION("if(REGEXMATCH(vlookup(B14,'Kings Ratings'!$A$2:$C$1000,3,false),""Crafting""),""Yes"","""")"),"Yes") -> Yes | N14: =IFERROR(__xludf.DUMMYFUNCTION("if(REGEXMATCH(vlookup(B14,'Kings Ratings'!$A$2:$C$1000,3,false),""Exploring""),""Yes"","""")"),"") | O14: =IFERROR(__xludf.DUMMYFUNCTION("if(REGEXMATCH(vlookup(B14,'Kings Ratings'!$A$2:$C$1000,3,false),""Farming""),""Yes"","""")"),"") | P14: =IFERROR(__xludf.DUMMYFUNCTION("if(REGEXMATCH(vlookup(B14,'Kings Ratings'!$A$2:$C$1000,3,false),""Cooking""),""Yes"","""")"),"") | Q14: =IFERROR(__xludf.DUMMYFUNCTION("if(REGEXMATCH(vlookup(B14,'Kings Ratings'!$A$2:$C$1000,3,false),""Event""),""Yes"","""")"),"")
A15: 77 | B15: Shimmer Stone | C15: =CONCATENATE("((",B15,"))") -> ((Shimmer Stone)) | D15: 47762 | E15: 21000 | F15: 7664 | G15: =VLOOKUP(B15,'Kings Ratings'!$A$2:$B$1000,2,false) -> 1 | H15: =if(G15=11,13,13-ROUNDDOWN(log(J15,4),0)) -> 0 | I15: =vlookup(A15,'202405 MM (Do Not Delete)'!$A$1:$G$1000,7,false) -> 227 | J15: =10000*F15+10*E15+D15 -> 76897762 | L15: =IFERROR(__xludf.DUMMYFUNCTION("if(REGEXMATCH(vlookup(B15,'Kings Ratings'!$A$2:$C$1000,3,false),""Fishing""),""Yes"","""")"),"") | M15: =IFERROR(__xludf.DUMMYFUNCTION("if(REGEXMATCH(vlookup(B15,'Kings Ratings'!$A$2:$C$1000,3,false),""Crafting""),""Yes"","""")"),"Yes") -> Yes | N15: =IFERROR(__xludf.DUMMYFUNCTION("if(REGEXMATCH(vlookup(B15,'Kings Ratings'!$A$2:$C$1000,3,false),""Exploring""),""Yes"","""")"),"") | O15: =IFERROR(__xludf.DUMMYFUNCTION("if(REGEXMATCH(vlookup(B15,'Kings Ratings'!$A$2:$C$1000,3,false),""Farming""),""Yes"","""")"),"") | P15: =IFERROR(__xludf.DUMMYFUNCTION("if(REGEXMATCH(vlookup(B15,'Kings Ratings'!$A$2:$C$1000,3,false),""Cooking""),""Yes"","""")"),"") | Q15: =IFERROR(__xludf.DUMMYFUNCTION("if(REGEXMATCH(vlookup(B15,'Kings Ratings'!$A$2:$C$1000,3,false),""Event""),""Yes"","""")"),"")
A16: 193 | B16: Rope | C16: =CONCATENATE("((",B16,"))") -> ((Rope)) | D16: 47364 | E16: 29729 | F16: 15253 | G16: =VLOOKUP(B16,'Kings Ratings'!$A$2:$B$1000,2,false) -> 1 | H16: =if(G16=11,13,13-ROUNDDOWN(log(J16,4),0)) -> 0 | I16: =vlookup(A16,'202405 MM (Do Not Delete)'!$A$1:$G$1000,7,false) -> 206 | J16: =10000*F16+10*E16+D16 -> 152874654 | L16: =IFERROR(__xludf.DUMMYFUNCTION("if(REGEXMATCH(vlookup(B16,'Kings Ratings'!$A$2:$C$1000,3,false),""Fishing""),""Yes"","""")"),"") | M16: =IFERROR(__xludf.DUMMYFUNCTION("if(REGEXMATCH(vlookup(B16,'Kings Ratings'!$A$2:$C$1000,3,false),""Crafting""),""Yes"","""")"),"Yes") -> Yes | N16: =IFERROR(__xludf.DUMMYFUNCTION("if(REGEXMATCH(vlookup(B16,'Kings Ratings'!$A$2:$C$1000,3,false),""Exploring""),""Yes"","""")"),"") | O16: =IFERROR(__xludf.DUMMYFUNCTION("if(REGEXMATCH(vlookup(B16,'Kings Ratings'!$A$2:$C$1000,3,false),""Farming""),""Yes"","""")"),"") | P16: =IFERROR(__xludf.DUMMYFUNCTION("if(REGEXMATCH(vlookup(B16,'Kings Ratings'!$A$2:$C$1000,3,false),""Cooking""),""Yes"","""")"),"") | Q16: =IFERROR(__xludf.DUMMYFUNCTION("if(REGEXMATCH(vlookup(B16,'Kings Ratings'!$A$2:$C$1000,3,false),""Event""),""Yes"","""")"),"")
A17: 145 | B17: Steel | C17: =CONCATENATE("((",B17,"))") -> ((Steel)) | D17: 46469 | E17: 27712 | F17: 12441 | G17: =VLOOKUP(B17,'Kings Ratings'!$A$2:$B$1000,2,false) -> 1 | H17: =if(G17=11,13,13-ROUNDDOWN(log(J17,4),0)) -> 0 | I17: =vlookup(A17,'202405 MM (Do Not Delete)'!$A$1:$G$1000,7,false) -> 251 | J17: =10000*F17+10*E17+D17 -> 124733589 | L17: =IFERROR(__xludf.DUMMYFUNCTION("if(REGEXMATCH(vlookup(B17,'Kings Ratings'!$A$2:$C$1000,3,false),""Fishing""),""Yes"","""")"),"") | M17: =IFERROR(__xludf.DUMMYFUNCTION("if(REGEXMATCH(vlookup(B17,'Kings Ratings'!$A$2:$C$1000,3,false),""Crafting""),""Yes"","""")"),"") | N17: =IFERROR(__xludf.DUMMYFUNCTION("if(REGEXMATCH(vlookup(B17,'Kings Ratings'!$A$2:$C$1000,3,false),""Exploring""),""Yes"","""")"),"") | O17: =IFERROR(__xludf.DUMMYFUNCTION("if(REGEXMATCH(vlookup(B17,'Kings Ratings'!$A$2:$C$1000,3,false),""Farming""),""Yes"","""")"),"") | P17: =IFERROR(__xludf.DUMMYFUNCTION("if(REGEXMATCH(vlookup(B17,'Kings Ratings'!$A$2:$C$1000,3,false),""Cooking""),""Yes"","""")"),"") | Q17: =IFERROR(__xludf.DUMMYFUNCTION("if(REGEXMATCH(vlookup(B17,'Kings Ratings'!$A$2:$C$1000,3,false),""Event""),""Yes"","""")"),"")
A18: 63 | B18: Trout | C18: =CONCATENATE("((",B18,"))") -> ((Trout)) | D18: 46177 | E18: 26256 | F18: 13373 | G18: =VLOOKUP(B18,'Kings Ratings'!$A$2:$B$1000,2,false) -> 1 | H18: =if(G18=11,13,13-ROUNDDOWN(log(J18,4),0)) -> 0 | I18: =vlookup(A18,'202405 MM (Do Not Delete)'!$A$1:$G$1000,7,false) -> 274 | J18: =10000*F18+10*E18+D18 -> 134038737 | L18: =IFERROR(__xludf.DUMMYFUNCTION("if(REGEXMATCH(vlookup(B18,'Kings Ratings'!$A$2:$C$1000,3,false),""Fishing""),""Yes"","""")"),"Yes") -> Yes | M18: =IFERROR(__xludf.DUMMYFUNCTION("if(REGEXMATCH(vlookup(B18,'Kings Ratings'!$A$2:$C$1000,3,false),""Crafting""),""Yes"","""")"),"") | N18: =IFERROR(__xludf.DUMMYFUNCTION("if(REGEXMATCH(vlookup(B18,'Kings Ratings'!$A$2:$C$1000,3,false),""Exploring""),""Yes"","""")"),"") | O18: =IFERROR(__xludf.DUMMYFUNCTION("if(REGEXMATCH(vlookup(B18,'Kings Ratings'!$A$2:$C$1000,3,false),""Farming""),""Yes"","""")"),"") | P18: =IFERROR(__xludf.DUMMYFUNCTION("if(REGEXMATCH(vlookup(B18,'Kings Ratings'!$A$2:$C$1000,3,false),""Cooking""),""Yes"","""")"),"") | Q18: =IFERROR(__xludf.DUMMYFUNCTION("if(REGEXMATCH(vlookup(B18,'Kings Ratings'!$A$2:$C$1000,3,false),""Event""),""Yes"","""")"),"")
A19: 25 | B19: Largemouth Bass | C19: =CONCATENATE("((",B19,"))") -> ((Largemouth Bass)) | D19: 45911 | E19: 23878 | F19: 12903 | G19: =VLOOKUP(B19,'Kings Ratings'!$A$2:$B$1000,2,false) -> 1 | H19: =if(G19=11,13,13-ROUNDDOWN(log(J19,4),0)) -> 0 | I19: =vlookup(A19,'202405 MM (Do Not Delete)'!$A$1:$G$1000,7,false) -> 254 | J19: =10000*F19+10*E19+D19 -> 129314691 | L19: =IFERROR(__xludf.DUMMYFUNCTION("if(REGEXMATCH(vlookup(B19,'Kings Ratings'!$A$2:$C$1000,3,false),""Fishing""),""Yes"","""")"),"Yes") -> Yes | M19: =IFERROR(__xludf.DUMMYFUNCTION("if(REGEXMATCH(vlookup(B19,'Kings Ratings'!$A$2:$C$1000,3,false),""Crafting""),""Yes"","""")"),"") | N19: =IFERROR(__xludf.DUMMYFUNCTION("if(REGEXMATCH(vlookup(B19,'Kings Ratings'!$A$2:$C$1000,3,false),""Exploring""),""Yes"","""")"),"") | O19: =IFERROR(__xludf.DUMMYFUNCTION("if(REGEXMATCH(vlookup(B19,'Kings Ratings'!$A$2:$C$1000,3,false),""Farming""),""Yes"","""")"),"") | P19: =IFERROR(__xludf.DUMMYFUNCTION("if(REGEXMATCH(vlookup(B19,'Kings Ratings'!$A$2:$C$1000,3,false),""Cooking""),""Yes"","""")"),"") | Q19: =IFERROR(__xludf.DUMMYFUNCTION("if(REGEXMATCH(vlookup(B19,'Kings Ratings'!$A$2:$C$1000,3,false),""Event""),""Yes"","""")"),"")
A20: 306 | B20: Swordfish | C20: =CONCATENATE("((",B20,"))") -> ((Swordfish)) | D20: 45848 | E20: 29791 | F20: 9867 | G20: =VLOOKUP(B20,'Kings Ratings'!$A$2:$B$1000,2,false) -> 1 | H20: =if(G20=11,13,13-ROUNDDOWN(log(J20,4),0)) -> 0 | I20: =vlookup(A20,'202405 MM (Do Not Delete)'!$A$1:$G$1000,7,false) -> 222 | J20: =10000*F20+10*E20+D20 -> 99013758 | L20: =IFERROR(__xludf.DUMMYFUNCTION("if(REGEXMATCH(vlookup(B20,'Kings Ratings'!$A$2:$C$1000,3,false),""Fishing""),""Yes"","""")"),"Yes") -> Yes | M20: =IFERROR(__xludf.DUMMYFUNCTION("if(REGEXMATCH(vlookup(B20,'Kings Ratings'!$A$2:$C$1000,3,false),""Crafting""),""Yes"","""")"),"") | N20: =IFERROR(__xludf.DUMMYFUNCTION("if(REGEXMATCH(vlookup(B20,'Kings Ratings'!$A$2:$C$1000,3,false),""Exploring""),""Yes"","""")"),"") | O20: =IFERROR(__xludf.DUMMYFUNCTION("if(REGEXMATCH(vlookup(B20,'Kings Ratings'!$A$2:$C$1000,3,false),""Farming""),""Yes"","""")"),"") | P20: =IFERROR(__xludf.DUMMYFUNCTION("if(REGEXMATCH(vlookup(B20,'Kings Ratings'!$A$2:$C$1000,3,false),""Cooking""),""Yes"","""")"),"") | Q20: =IFERROR(__xludf.DUMMYFUNCTION("if(REGEXMATCH(vlookup(B20,'Kings Ratings'!$A$2:$C$1000,3,false),""Event""),""Yes"","""")"),"")
A21: 194 | B21: Fishing Net | C21: =CONCATENATE("((",B21,"))") -> ((Fishing Net)) | D21: 45431 | E21: 27323 | F21: 13902 | G21: =VLOOKUP(B21,'Kings Ratings'!$A$2:$B$1000,2,false) -> 2 | H21: =if(G21=11,13,13-ROUNDDOWN(log(J21,4),0)) -> 0 | I21: =vlookup(A21,'202405 MM (Do Not Delete)'!$A$1:$G$1000,7,false) -> 211 | J21: =10000*F21+10*E21+D21 -> 139338661 | L21: =IFERROR(__xludf.DUMMYFUNCTION("if(REGEXMATCH(vlookup(B21,'Kings Ratings'!$A$2:$C$1000,3,false),""Fishing""),""Yes"","""")"),"") | M21: =IFERROR(__xludf.DUMMYFUNCTION("if(REGEXMATCH(vlookup(B21,'Kings Ratings'!$A$2:$C$1000,3,false),""Crafting""),""Yes"","""")"),"Yes") -> Yes | N21: =IFERROR(__xludf.DUMMYFUNCTION("if(REGEXMATCH(vlookup(B21,'Kings Ratings'!$A$2:$C$1000,3,false),""Exploring""),""Yes"","""")"),"") | O21: =IFERROR(__xludf.DUMMYFUNCTION("if(REGEXMATCH(vlookup(B21,'Kings Ratings'!$A$2:$C$1000,3,false),""Farming""),""Yes"","""")"),"") | P21: =IFERROR(__xludf.DUMMYFUNCTION("if(REGEXMATCH(vlookup(B21,'Kings Ratings'!$A$2:$C$1000,3,false),""Cooking""),""Yes"","""")"),"") | Q21: =IFERROR(__xludf.DUMMYFUNCTION("if(REGEXMATCH(vlookup(B21,'Kings Ratings'!$A$2:$C$1000,3,false),""Event""),""Yes"","""")"),"")
A22: 167 | B22: Sturdy Shield | C22: =CONCATENATE("((",B22,"))") -> ((Sturdy Shield)) | D22: 45023 | E22: 20631 | F22: 6417 | G22: =VLOOKUP(B22,'Kings Ratings'!$A$2:$B$1000,2,false) -> 1 | H22: =if(G22=11,13,13-ROUNDDOWN(log(J22,4),0)) -> 1 | I22: =vlookup(A22,'202405 MM (Do Not Delete)'!$A$1:$G$1000,7,false) -> 239 | J22: =10000*F22+10*E22+D22 -> 64421333 | L22: =IFERROR(__xludf.DUMMYFUNCTION("if(REGEXMATCH(vlookup(B22,'Kings Ratings'!$A$2:$C$1000,3,false),""Fishing""),""Yes"","""")"),"") | M22: =IFERROR(__xludf.DUMMYFUNCTION("if(REGEXMATCH(vlookup(B22,'Kings Ratings'!$A$2:$C$1000,3,false),""Crafting""),""Yes"","""")"),"Yes") -> Yes | N22: =IFERROR(__xludf.DUMMYFUNCTION("if(REGEXMATCH(vlookup(B22,'Kings Ratings'!$A$2:$C$1000,3,false),""Exploring""),""Yes"","""")"),"") | O22: =IFERROR(__xludf.DUMMYFUNCTION("if(REGEXMATCH(vlookup(B22,'Kings Ratings'!$A$2:$C$1000,3,false),""Farming""),""Yes"","""")"),"") | P22: =IFERROR(__xludf.DUMMYFUNCTION("if(REGEXMATCH(vlookup(B22,'Kings Ratings'!$A$2:$C$1000,3,false),""Cooking""),""Yes"","""")"),"") | Q22: =IFERROR(__xludf.DUMMYFUNCTION("if(REGEXMATCH(vlookup(B22,'Kings Ratings'!$A$2:$C$1000,3,false),""Event""),""Yes"","""")"),"")
A23: 307 | B23: Barracuda | C23: =CONCATENATE("((",B23,"))") -> ((Barracuda)) | D23: 44524 | E23: 27593 | F23: 8966 | G23: =VLOOKUP(B23,'Kings Ratings'!$A$2:$B$1000,2,false) -> 1 | H23: =if(G23=11,13,13-ROUNDDOWN(log(J23,4),0)) -> 0 | I23: =vlookup(A23,'202405 MM (Do Not Delete)'!$A$1:$G$1000,7,false) -> 225 | J23: =10000*F23+10*E23+D23 -> 89980454 | L23: =IFERROR(__xludf.DUMMYFUNCTION("if(REGEXMATCH(vlookup(B23,'Kings Ratings'!$A$2:$C$1000,3,false),""Fishing""),""Yes"","""")"),"Yes") -> Yes | M23: =IFERROR(__xludf.DUMMYFUNCTION("if(REGEXMATCH(vlookup(B23,'Kings Ratings'!$A$2:$C$1000,3,false),""Crafting""),""Yes"","""")"),"") | N23: =IFERROR(__xludf.DUMMYFUNCTION("if(REGEXMATCH(vlookup(B23,'Kings Ratings'!$A$2:$C$1000,3,false),""Exploring""),""Yes"","""")"),"") | O23: =IFERROR(__xludf.DUMMYFUNCTION("if(REGEXMATCH(vlookup(B23,'Kings Ratings'!$A$2:$C$1000,3,false),""Farming""),""Yes"","""")"),"") | P23: =IFERROR(__xludf.DUMMYFUNCTION("if(REGEXMATCH(vlookup(B23,'Kings Ratings'!$A$2:$C$1000,3,false),""Cooking""),""Yes"","""")"),"") | Q23: =IFERROR(__xludf.DUMMYFUNCTION("if(REGEXMATCH(vlookup(B23,'Kings Ratings'!$A$2:$C$1000,3,false),""Event""),""Yes"","""")"),"")
A24: 198 | B24: Mackerel | C24: =CONCATENATE("((",B24,"))") -> ((Mackerel)) | D24: 44464 | E24: 26145 | F24: 13806 | G24: =VLOOKUP(B24,'Kings Ratings'!$A$2:$B$1000,2,false) -> 1 | H24: =if(G24=11,13,13-ROUNDDOWN(log(J24,4),0)) -> 0 | I24: =vlookup(A24,'202405 MM (Do Not Delete)'!$A$1:$G$1000,7,false) -> 216 | J24: =10000*F24+10*E24+D24 -> 138365914 | L24: =IFERROR(__xludf.DUMMYFUNCTION("if(REGEXMATCH(vlookup(B24,'Kings Ratings'!$A$2:$C$1000,3,false),""Fishing""),""Yes"","""")"),"Yes") -> Yes | M24: =IFERROR(__xludf.DUMMYFUNCTION("if(REGEXMATCH(vlookup(B24,'Kings Ratings'!$A$2:$C$1000,3,false),""Crafting""),""Yes"","""")"),"") | N24: =IFERROR(__xludf.DUMMYFUNCTION("if(REGEXMATCH(vlookup(B24,'Kings Ratings'!$A$2:$C$1000,3,false),""Exploring""),""Yes"","""")"),"") | O24: =IFERROR(__xludf.DUMMYFUNCTION("if(REGEXMATCH(vlookup(B24,'Kings Ratings'!$A$2:$C$1000,3,false),""Farming""),""Yes"","""")"),"") | P24: =IFERROR(__xludf.DUMMYFUNCTION("if(REGEXMATCH(vlookup(B24,'Kings Ratings'!$A$2:$C$1000,3,false),""Cooking""),""Yes"","""")"),"") | Q24: =IFERROR(__xludf.DUMMYFUNCTION("if(REGEXMATCH(vlookup(B24,'Kings Ratings'!$A$2:$C$1000,3,false),""Event""),""Yes"","""")"),"")
A25: 65 | B25: Corn | C25: =CONCATENATE("((",B25,"))") -> ((Corn)) | D25: 43435 | E25: 10526 | F25: 786 | G25: =VLOOKUP(B25,'Kings Ratings'!$A$2:$B$1000,2,false) -> 7 | H25: =if(G25=11,13,13-ROUNDDOWN(log(J25,4),0)) -> 2 | I25: =vlookup(A25,'202405 MM (Do Not Delete)'!$A$1:$G$1000,7,false) | J25: =10000*F25+10*E25+D25 -> 8008695 | L25: =IFERROR(__xludf.DUMMYFUNCTION("if(REGEXMATCH(vlookup(B25,'Kings Ratings'!$A$2:$C$1000,3,false),""Fishing""),""Yes"","""")"),"") | M25: =IFERROR(__xludf.DUMMYFUNCTION("if(REGEXMATCH(vlookup(B25,'Kings Ratings'!$A$2:$C$1000,3,false),""Crafting""),""Yes"","""")"),"") | N25: =IFERROR(__xludf.DUMMYFUNCTION("if(REGEXMATCH(vlookup(B25,'Kings Ratings'!$A$2:$C$1000,3,false),""Exploring""),""Yes"","""")"),"") | O25: =IFERROR(__xludf.DUMMYFUNCTION("if(REGEXMATCH(vlookup(B25,'Kings Ratings'!$A$2:$C$1000,3,false),""Farming""),""Yes"","""")"),"Yes") -> Yes | P25: =IFERROR(__xludf.DUMMYFUNCTION("if(REGEXMATCH(vlookup(B25,'Kings Ratings'!$A$2:$C$1000,3,false),""Cooking""),""Yes"","""")"),"") | Q25: =IFERROR(__xludf.DUMMYFUNCTION("if(REGEXMATCH(vlookup(B25,'Kings Ratings'!$A$2:$C$1000,3,false),""Event""),""Yes"","""")"),"")
A26: 84 | B26: Orange Juice | C26: =CONCATENATE("((",B26,"))") -> ((Orange Juice)) | D26: 43373 | E26: 18514 | F26: 5315 | G26: =VLOOKUP(B26,'Kings Ratings'!$A$2:$B$1000,2,false) -> 3 | H26: =if(G26=11,13,13-ROUNDDOWN(log(J26,4),0)) -> 1 | I26: =vlookup(A26,'202405 MM (Do Not Delete)'!$A$1:$G$1000,7,false) -> 239 | J26: =10000*F26+10*E26+D26 -> 53378513 | L26: =IFERROR(__xludf.DUMMYFUNCTION("if(REGEXMATCH(vlookup(B26,'Kings Ratings'!$A$2:$C$1000,3,false),""Fishing""),""Yes"","""")"),"") | M26: =IFERROR(__xludf.DUMMYFUNCTION("if(REGEXMATCH(vlookup(B26,'Kings Ratings'!$A$2:$C$1000,3,false),""Crafting""),""Yes"","""")"),"Yes") -> Yes | N26: =IFERROR(__xludf.DUMMYFUNCTION("if(REGEXMATCH(vlookup(B26,'Kings Ratings'!$A$2:$C$1000,3,false),""Exploring""),""Yes"","""")"),"") | O26: =IFERROR(__xludf.DUMMYFUNCTION("if(REGEXMATCH(vlookup(B26,'Kings Ratings'!$A$2:$C$1000,3,false),""Farming""),""Yes"","""")"),"") | P26: =IFERROR(__xludf.DUMMYFUNCTION("if(REGEXMATCH(vlookup(B26,'Kings Ratings'!$A$2:$C$1000,3,false),""Cooking""),""Yes"","""")"),"") | Q26: =IFERROR(__xludf.DUMMYFUNCTION("if(REGEXMATCH(vlookup(B26,'Kings Ratings'!$A$2:$C$1000,3,false),""Event""),""Yes"","""")"),"")
A27: 308 | B27: Sea Catfish | C27: =CONCATENATE("((",B27,"))") -> ((Sea Catfish)) | D27: 43161 | E27: 25914 | F27: 8330 | G27: =VLOOKUP(B27,'Kings Ratings'!$A$2:$B$1000,2,false) -> 1 | H27: =if(G27=11,13,13-ROUNDDOWN(log(J27,4),0)) -> 0 | I27: =vlookup(A27,'202405 MM (Do Not Delete)'!$A$1:$G$1000,7,false) -> 229 | J27: =10000*F27+10*E27+D27 -> 83602301 | L27: =IFERROR(__xludf.DUMMYFUNCTION("if(REGEXMATCH(vlookup(B27,'Kings Ratings'!$A$2:$C$1000,3,false),""Fishing""),""Yes"","""")"),"Yes") -> Yes | M27: =IFERROR(__xludf.DUMMYFUNCTION("if(REGEXMATCH(vlookup(B27,'Kings Ratings'!$A$2:$C$1000,3,false),""Crafting""),""Yes"","""")"),"") | N27: =IFERROR(__xludf.DUMMYFUNCTION("if(REGEXMATCH(vlookup(B27,'Kings Ratings'!$A$2:$C$1000,3,false),""Exploring""),""Yes"","""")"),"") | O27: =IFERROR(__xludf.DUMMYFUNCTION("if(REGEXMATCH(vlookup(B27,'Kings Ratings'!$A$2:$C$1000,3,false),""Farming""),""Yes"","""")"),"") | P27: =IFERROR(__xludf.DUMMYFUNCTION("if(REGEXMATCH(vlookup(B27,'Kings Ratings'!$A$2:$C$1000,3,false),""Cooking""),""Yes"","""")"),"") | Q27: =IFERROR(__xludf.DUMMYFUNCTION("if(REGEXMATCH(vlookup(B27,'Kings Ratings'!$A$2:$C$1000,3,false),""Event""),""Yes"","""")"),"")
A28: 309 | B28: Plumbfish | C28: =CONCATENATE("((",B28,"))") -> ((Plumbfish)) | D28: 42655 | E28: 24898 | F28: 8153 | G28: =VLOOKUP(B28,'Kings Ratings'!$A$2:$B$1000,2,false) -> 1 | H28: =if(G28=11,13,13-ROUNDDOWN(log(J28,4),0)) -> 0 | I28: =vlookup(A28,'202405 MM (Do Not Delete)'!$A$1:$G$1000,7,false) -> 230 | J28: =10000*F28+10*E28+D28 -> 81821635 | L28: =IFERROR(__xludf.DUMMYFUNCTION("if(REGEXMATCH(vlookup(B28,'Kings Ratings'!$A$2:$C$1000,3,false),""Fishing""),""Yes"","""")"),"Yes") -> Yes | M28: =IFERROR(__xludf.DUMMYFUNCTION("if(REGEXMATCH(vlookup(B28,'Kings Ratings'!$A$2:$C$1000,3,false),""Crafting""),""Yes"","""")"),"") | N28: =IFERROR(__xludf.DUMMYFUNCTION("if(REGEXMATCH(vlookup(B28,'Kings Ratings'!$A$2:$C$1000,3,false),""Exploring""),""Yes"","""")"),"") | O28: =IFERROR(__xludf.DUMMYFUNCTION("if(REGEXMATCH(vlookup(B28,'Kings Ratings'!$A$2:$C$1000,3,false),""Farming""),""Yes"","""")"),"") | P28: =IFERROR(__xludf.DUMMYFUNCTION("if(REGEXMATCH(vlookup(B28,'Kings Ratings'!$A$2:$C$1000,3,false),""Cooking""),""Yes"","""")"),"") | Q28: =IFERROR(__xludf.DUMMYFUNCTION("if(REGEXMATCH(vlookup(B28,'Kings Ratings'!$A$2:$C$1000,3,false),""Event""),""Yes"","""")"),"")
A29: 368 | B29: Lantern | C29: =CONCATENATE("((",B29,"))") -> ((Lantern)) | D29: 41305 | E29: 13937 | F29: 2254 | G29: =VLOOKUP(B29,'Kings Ratings'!$A$2:$B$1000,2,false) -> 2 | H29: =if(G29=11,13,13-ROUNDDOWN(log(J29,4),0)) -> 1 | I29: =vlookup(A29,'202405 MM (Do Not Delete)'!$A$1:$G$1000,7,false) -> 280 | J29: =10000*F29+10*E29+D29 -> 22720675 | L29: =IFERROR(__xludf.DUMMYFUNCTION("if(REGEXMATCH(vlookup(B29,'Kings Ratings'!$A$2:$C$1000,3,false),""Fishing""),""Yes"","""")"),"") | M29: =IFERROR(__xludf.DUMMYFUNCTION("if(REGEXMATCH(vlookup(B29,'Kings Ratings'!$A$2:$C$1000,3,false),""Crafting""),""Yes"","""")"),"Yes") -> Yes | N29: =IFERROR(__xludf.DUMMYFUNCTION("if(REGEXMATCH(vlookup(B29,'Kings Ratings'!$A$2:$C$1000,3,false),""Exploring""),""Yes"","""")"),"") | O29: =IFERROR(__xludf.DUMMYFUNCTION("if(REGEXMATCH(vlookup(B29,'Kings Ratings'!$A$2:$C$1000,3,false),""Farming""),""Yes"","""")"),"") | P29: =IFERROR(__xludf.DUMMYFUNCTION("if(REGEXMATCH(vlookup(B29,'Kings Ratings'!$A$2:$C$1000,3,false),""Cooking""),""Yes"","""")"),"") | Q29: =IFERROR(__xludf.DUMMYFUNCTION("if(REGEXMATCH(vlookup(B29,'Kings Ratings'!$A$2:$C$1000,3,false),""Event""),""Yes"","""")"),"")
A30: 310 | B30: Spiral Shell | C30: =CONCATENATE("((",B30,"))") -> ((Spiral Shell)) | D30: 41236 | E30: 23820 | F30: 7719 | G30: =VLOOKUP(B30,'Kings Ratings'!$A$2:$B$1000,2,false) -> 1 | H30: =if(G30=11,13,13-ROUNDDOWN(log(J30,4),0)) -> 0 | I30: =vlookup(A30,'202405 MM (Do Not Delete)'!$A$1:$G$1000,7,false) -> 232 | J30: =10000*F30+10*E30+D30 -> 77469436 | L30: =IFERROR(__xludf.DUMMYFUNCTION("if(REGEXMATCH(vlookup(B30,'Kings Ratings'!$A$2:$C$1000,3,false),""Fishing""),""Yes"","""")"),"Yes") -> Yes | M30: =IFERROR(__xludf.DUMMYFUNCTION("if(REGEXMATCH(vlookup(B30,'Kings Ratings'!$A$2:$C$1000,3,false),""Crafting""),""Yes"","""")"),"") | N30: =IFERROR(__xludf.DUMMYFUNCTION("if(REGEXMATCH(vlookup(B30,'Kings Ratings'!$A$2:$C$1000,3,false),""Exploring""),""Yes"","""")"),"") | O30: =IFERROR(__xludf.DUMMYFUNCTION("if(REGEXMATCH(vlookup(B30,'Kings Ratings'!$A$2:$C$1000,3,false),""Farming""),""Yes"","""")"),"") | P30: =IFERROR(__xludf.DUMMYFUNCTION("if(REGEXMATCH(vlookup(B30,'Kings Ratings'!$A$2:$C$1000,3,false),""Cooking""),""Yes"","""")"),"") | Q30: =IFERROR(__xludf.DUMMYFUNCTION("if(REGEXMATCH(vlookup(B30,'Kings Ratings'!$A$2:$C$1000,3,false),""Event""),""Yes"","""")"),"")
A31: 110 | B31: Leather | C31: =CONCATENATE("((",B31,"))") -> ((Leather)) | D31: 41041 | E31: 18077 | F31: 6888 | G31: =VLOOKUP(B31,'Kings Ratings'!$A$2:$B$1000,2,false) -> 1 | H31: =if(G31=11,13,13-ROUNDDOWN(log(J31,4),0)) -> 0 | I31: =vlookup(A31,'202405 MM (Do Not Delete)'!$A$1:$G$1000,7,false) -> 231 | J31: =10000*F31+10*E31+D31 -> 69101811 | L31: =IFERROR(__xludf.DUMMYFUNCTION("if(REGEXMATCH(vlookup(B31,'Kings Ratings'!$A$2:$C$1000,3,false),""Fishing""),""Yes"","""")"),"") | M31: =IFERROR(__xludf.DUMMYFUNCTION("if(REGEXMATCH(vlookup(B31,'Kings Ratings'!$A$2:$C$1000,3,false),""Crafting""),""Yes"","""")"),"Yes") -> Yes | N31: =IFERROR(__xludf.DUMMYFUNCTION("if(REGEXMATCH(vlookup(B31,'Kings Ratings'!$A$2:$C$1000,3,false),""Exploring""),""Yes"","""")"),"") | O31: =IFERROR(__xludf.DUMMYFUNCTION("if(REGEXMATCH(vlookup(B31,'Kings Ratings'!$A$2:$C$1000,3,false),""Farming""),""Yes"","""")"),"") | P31: =IFERROR(__xludf.DUMMYFUNCTION("if(REGEXMATCH(vlookup(B31,'Kings Ratings'!$A$2:$C$1000,3,false),""Cooking""),""Yes"","""")"),"") | Q31: =IFERROR(__xludf.DUMMYFUNCTION("if(REGEXMATCH(vlookup(B31,'Kings Ratings'!$A$2:$C$1000,3,false),""Event""),""Yes"","""")"),"")
A32: 101 | B32: Conch Shell | C32: =CONCATENATE("((",B32,"))") -> ((Conch Shell)) | D32: 40922 | E32: 27718 | F32: 15021 | G32: =VLOOKUP(B32,'Kings Ratings'!$A$2:$B$1000,2,false) -> 1 | H32: =if(G32=11,13,13-ROUNDDOWN(log(J32,4),0)) -> 0 | I32: =vlookup(A32,'202405 MM (Do Not Delete)'!$A$1:$G$1000,7,false) -> 210 | J32: =10000*F32+10*E32+D32 -> 150528102 | L32: =IFERROR(__xludf.DUMMYFUNCTION("if(REGEXMATCH(vlookup(B32,'Kings Ratings'!$A$2:$C$1000,3,false),""Fishing""),""Yes"","""")"),"Yes") -> Yes | M32: =IFERROR(__xludf.DUMMYFUNCTION("if(REGEXMATCH(vlookup(B32,'Kings Ratings'!$A$2:$C$1000,3,false),""Crafting""),""Yes"","""")"),"") | N32: =IFERROR(__xludf.DUMMYFUNCTION("if(REGEXMATCH(vlookup(B32,'Kings Ratings'!$A$2:$C$1000,3,false),""Exploring""),""Yes"","""")"),"") | O32: =IFERROR(__xludf.DUMMYFUNCTION("if(REGEXMATCH(vlookup(B32,'Kings Ratings'!$A$2:$C$1000,3,false),""Farming""),""Yes"","""")"),"") | P32: =IFERROR(__xludf.DUMMYFUNCTION("if(REGEXMATCH(vlookup(B32,'Kings Ratings'!$A$2:$C$1000,3,false),""Cooking""),""Yes"","""")"),"") | Q32: =IFERROR(__xludf.DUMMYFUNCTION("if(REGEXMATCH(vlookup(B32,'Kings Ratings'!$A$2:$C$1000,3,false),""Event""),""Yes"","""")"),"")
A33: 97 | B33: Clam Shell | C33: =CONCATENATE("((",B33,"))") -> ((Clam Shell)) | D33: 40826 | E33: 27710 | F33: 15023 | G33: =VLOOKUP(B33,'Kings Ratings'!$A$2:$B$1000,2,false) -> 1 | H33: =if(G33=11,13,13-ROUNDDOWN(log(J33,4),0)) -> 0 | I33: =vlookup(A33,'202405 MM (Do Not Delete)'!$A$1:$G$1000,7,false) -> 209 | J33: =10000*F33+10*E33+D33 -> 150547926 | L33: =IFERROR(__xludf.DUMMYFUNCTION("if(REGEXMATCH(vlookup(B33,'Kings Ratings'!$A$2:$C$1000,3,false),""Fishing""),""Yes"","""")"),"Yes") -> Yes | M33: =IFERROR(__xludf.DUMMYFUNCTION("if(REGEXMATCH(vlookup(B33,'Kings Ratings'!$A$2:$C$1000,3,false),""Crafting""),""Yes"","""")"),"") | N33: =IFERROR(__xludf.DUMMYFUNCTION("if(REGEXMATCH(vlookup(B33,'Kings Ratings'!$A$2:$C$1000,3,false),""Exploring""),""Yes"","""")"),"") | O33: =IFERROR(__xludf.DUMMYFUNCTION("if(REGEXMATCH(vlookup(B33,'Kings Ratings'!$A$2:$C$1000,3,false),""Farming""),""Yes"","""")"),"") | P33: =IFERROR(__xludf.DUMMYFUNCTION("if(REGEXMATCH(vlookup(B33,'Kings Ratings'!$A$2:$C$1000,3,false),""Cooking""),""Yes"","""")"),"") | Q33: =IFERROR(__xludf.DUMMYFUNCTION("if(REGEXMATCH(vlookup(B33,'Kings Ratings'!$A$2:$C$1000,3,false),""Event""),""Yes"","""")"),"")
A34: 311 | B34: Serpent Eel | C34: =CONCATENATE("((",B34,"))") -> ((Serpent Eel)) | D34: 40515 | E34: 23251 | F34: 7618 | G34: =VLOOKUP(B34,'Kings Ratings'!$A$2:$B$1000,2,false) -> 1 | H34: =if(G34=11,13,13-ROUNDDOWN(log(J34,4),0)) -> 0 | I34: =vlookup(A34,'202405 MM (Do Not Delete)'!$A$1:$G$1000,7,false) -> 233 | J34: =10000*F34+10*E34+D34 -> 76453025 | L34: =IFERROR(__xludf.DUMMYFUNCTION("if(REGEXMATCH(vlookup(B34,'Kings Ratings'!$A$2:$C$1000,3,false),""Fishing""),""Yes"","""")"),"Yes") -> Yes | M34: =IFERROR(__xludf.DUMMYFUNCTION("if(REGEXMATCH(vlookup(B34,'Kings Ratings'!$A$2:$C$1000,3,false),""Crafting""),""Yes"","""")"),"") | N34: =IFERROR(__xludf.DUMMYFUNCTION("if(REGEXMATCH(vlookup(B34,'Kings Ratings'!$A$2:$C$1000,3,false),""Exploring""),""Yes"","""")"),"") | O34: =IFERROR(__xludf.DUMMYFUNCTION("if(REGEXMATCH(vlookup(B34,'Kings Ratings'!$A$2:$C$1000,3,false),""Farming""),""Yes"","""")"),"") | P34: =IFERROR(__xludf.DUMMYFUNCTION("if(REGEXMATCH(vlookup(B34,'Kings Ratings'!$A$2:$C$1000,3,false),""Cooking""),""Yes"","""")"),"") | Q34: =IFERROR(__xludf.DUMMYFUNCTION("if(REGEXMATCH(vlookup(B34,'Kings Ratings'!$A$2:$C$1000,3,false),""Event""),""Yes"","""")"),"")
A35: 301 | B35: Fancy Pipe | C35: =CONCATENATE("((",B35,"))") -> ((Fancy Pipe)) | D35: 40088 | E35: 18245 | F35: 5929 | G35: =VLOOKUP(B35,'Kings Ratings'!$A$2:$B$1000,2,false) -> 1 | H35: =if(G35=11,13,13-ROUNDDOWN(log(J35,4),0)) -> 1 | I35: =vlookup(A35,'202405 MM (Do Not Delete)'!$A$1:$G$1000,7,false) -> 241 | J35: =10000*F35+10*E35+D35 -> 59512538 | L35: =IFERROR(__xludf.DUMMYFUNCTION("if(REGEXMATCH(vlookup(B35,'Kings Ratings'!$A$2:$C$1000,3,false),""Fishing""),""Yes"","""")"),"") | M35: =IFERROR(__xludf.DUMMYFUNCTION("if(REGEXMATCH(vlookup(B35,'Kings Ratings'!$A$2:$C$1000,3,false),""Crafting""),""Yes"","""")"),"Yes") -> Yes | N35: =IFERROR(__xludf.DUMMYFUNCTION("if(REGEXMATCH(vlookup(B35,'Kings Ratings'!$A$2:$C$1000,3,false),""Exploring""),""Yes"","""")"),"") | O35: =IFERROR(__xludf.DUMMYFUNCTION("if(REGEXMATCH(vlookup(B35,'Kings Ratings'!$A$2:$C$1000,3,false),""Farming""),""Yes"","""")"),"") | P35: =IFERROR(__xludf.DUMMYFUNCTION("if(REGEXMATCH(vlookup(B35,'Kings Ratings'!$A$2:$C$1000,3,false),""Cooking""),""Yes"","""")"),"") | Q35: =IFERROR(__xludf.DUMMYFUNCTION("if(REGEXMATCH(vlookup(B35,'Kings Ratings'!$A$2:$C$1000,3,false),""Event""),""Yes"","""")"),"")
A36: 312 | B36: Ruby Coral | C36: =CONCATENATE("((",B36,"))") -> ((Ruby Coral)) | D36: 39805 | E36: 22649 | F36: 7345 | G36: =VLOOKUP(B36,'Kings Ratings'!$A$2:$B$1000,2,false) -> 1 | H36: =if(G36=11,13,13-ROUNDDOWN(log(J36,4),0)) -> 0 | I36: =vlookup(A36,'202405 MM (Do Not Delete)'!$A$1:$G$1000,7,false) -> 234 | J36: =10000*F36+10*E36+D36 -> 73716295 | L36: =IFERROR(__xludf.DUMMYFUNCTION("if(REGEXMATCH(vlookup(B36,'Kings Ratings'!$A$2:$C$1000,3,false),""Fishing""),""Yes"","""")"),"Yes") -> Yes | M36: =IFERROR(__xludf.DUMMYFUNCTION("if(REGEXMATCH(vlookup(B36,'Kings Ratings'!$A$2:$C$1000,3,false),""Crafting""),""Yes"","""")"),"") | N36: =IFERROR(__xludf.DUMMYFUNCTION("if(REGEXMATCH(vlookup(B36,'Kings Ratings'!$A$2:$C$1000,3,false),""Exploring""),""Yes"","""")"),"") | O36: =IFERROR(__xludf.DUMMYFUNCTION("if(REGEXMATCH(vlookup(B36,'Kings Ratings'!$A$2:$C$1000,3,false),""Farming""),""Yes"","""")"),"") | P36: =IFERROR(__xludf.DUMMYFUNCTION("if(REGEXMATCH(vlookup(B36,'Kings Ratings'!$A$2:$C$1000,3,false),""Cooking""),""Yes"","""")"),"") | Q36: =IFERROR(__xludf.DUMMYFUNCTION("if(REGEXMATCH(vlookup(B36,'Kings Ratings'!$A$2:$C$1000,3,false),""Event""),""Yes"","""")"),"")
A37: 232 | B37: Flamejack | C37: =CONCATENATE("((",B37,"))") -> ((Flamejack)) | D37: 39632 | E37: 20827 | F37: 9228 | G37: =VLOOKUP(B37,'Kings Ratings'!$A$2:$B$1000,2,false) -> 1 | H37: =if(G37=11,13,13-ROUNDDOWN(log(J37,4),0)) -> 0 | I37: =vlookup(A37,'202405 MM (Do Not Delete)'!$A$1:$G$1000,7,false) -> 224 | J37: =10000*F37+10*E37+D37 -> 92527902 | L37: =IFERROR(__xludf.DUMMYFUNCTION("if(REGEXMATCH(vlookup(B37,'Kings Ratings'!$A$2:$C$1000,3,false),""Fishing""),""Yes"","""")"),"Yes") -> Yes | M37: =IFERROR(__xludf.DUMMYFUNCTION("if(REGEXMATCH(vlookup(B37,'Kings Ratings'!$A$2:$C$1000,3,false),""Crafting""),""Yes"","""")"),"") | N37: =IFERROR(__xludf.DUMMYFUNCTION("if(REGEXMATCH(vlookup(B37,'Kings Ratings'!$A$2:$C$1000,3,false),""Exploring""),""Yes"","""")"),"") | O37: =IFERROR(__xludf.DUMMYFUNCTION("if(REGEXMATCH(vlookup(B37,'Kings Ratings'!$A$2:$C$1000,3,false),""Farming""),""Yes"","""")"),"") | P37: =IFERROR(__xludf.DUMMYFUNCTION("if(REGEXMATCH(vlookup(B37,'Kings Ratings'!$A$2:$C$1000,3,false),""Cooking""),""Yes"","""")"),"") | Q37: =IFERROR(__xludf.DUMMYFUNCTION("if(REGEXMATCH(vlookup(B37,'Kings Ratings'!$A$2:$C$1000,3,false),""Event""),""Yes"","""")"),"")
A38: 86 | B38: Lemonade | C38: =CONCATENATE("((",B38,"))") -> ((Lemonade)) | D38: 39332 | E38: 17342 | F38: 4893 | G38: =VLOOKUP(B38,'Kings Ratings'!$A$2:$B$1000,2,false) -> 3 | H38: =if(G38=11,13,13-ROUNDDOWN(log(J38,4),0)) -> 1 | I38: =vlookup(A38,'202405 MM (Do Not Delete)'!$A$1:$G$1000,7,false) -> 242 | J38: =10000*F38+10*E38+D38 -> 49142752 | L38: =IFERROR(__xludf.DUMMYFUNCTION("if(REGEXMATCH(vlookup(B38,'Kings Ratings'!$A$2:$C$1000,3,false),""Fishing""),""Yes"","""")"),"") | M38: =IFERROR(__xludf.DUMMYFUNCTION("if(REGEXMATCH(vlookup(B38,'Kings Ratings'!$A$2:$C$1000,3,false),""Crafting""),""Yes"","""")"),"Yes") -> Yes | N38: =IFERROR(__xludf.DUMMYFUNCTION("if(REGEXMATCH(vlookup(B38,'Kings Ratings'!$A$2:$C$1000,3,false),""Exploring""),""Yes"","""")"),"") | O38: =IFERROR(__xludf.DUMMYFUNCTION("if(REGEXMATCH(vlookup(B38,'Kings Ratings'!$A$2:$C$1000,3,false),""Farming""),""Yes"","""")"),"") | P38: =IFERROR(__xludf.DUMMYFUNCTION("if(REGEXMATCH(vlookup(B38,'Kings Ratings'!$A$2:$C$1000,3,false),""Cooking""),""Yes"","""")"),"") | Q38: =IFERROR(__xludf.DUMMYFUNCTION("if(REGEXMATCH(vlookup(B38,'Kings Ratings'!$A$2:$C$1000,3,false),""Event""),""Yes"","""")"),"")
A39: 58 | B39: Small Prawn | C39: =CONCATENATE("((",B39,"))") -> ((Small Prawn)) | D39: 37609 | E39: 24636 | F39: 12347 | G39: =VLOOKUP(B39,'Kings Ratings'!$A$2:$B$1000,2,false) -> 1 | H39: =if(G39=11,13,13-ROUNDDOWN(log(J39,4),0)) -> 0 | I39: =vlookup(A39,'202405 MM (Do Not Delete)'!$A$1:$G$1000,7,false) -> 256 | J39: =10000*F39+10*E39+D39 -> 123753969 | L39: =IFERROR(__xludf.DUMMYFUNCTION("if(REGEXMATCH(vlookup(B39,'Kings Ratings'!$A$2:$C$1000,3,false),""Fishing""),""Yes"","""")"),"Yes") -> Yes | M39: =IFERROR(__xludf.DUMMYFUNCTION("if(REGEXMATCH(vlookup(B39,'Kings Ratings'!$A$2:$C$1000,3,false),""Crafting""),""Yes"","""")"),"") | N39: =IFERROR(__xludf.DUMMYFUNCTION("if(REGEXMATCH(vlookup(B39,'Kings Ratings'!$A$2:$C$1000,3,false),""Exploring""),""Yes"","""")"),"") | O39: =IFERROR(__xludf.DUMMYFUNCTION("if(REGEXMATCH(vlookup(B39,'Kings Ratings'!$A$2:$C$1000,3,false),""Farming""),""Yes"","""")"),"") | P39: =IFERROR(__xludf.DUMMYFUNCTION("if(REGEXMATCH(vlookup(B39,'Kings Ratings'!$A$2:$C$1000,3,false),""Cooking""),""Yes"","""")"),"") | Q39: =IFERROR(__xludf.DUMMYFUNCTION("if(REGEXMATCH(vlookup(B39,'Kings Ratings'!$A$2:$C$1000,3,false),""Event""),""Yes"","""")"),"")
A40: 392 | B40: Steel Wire | C40: =CONCATENATE("((",B40,"))") -> ((Steel Wire)) | D40: 37444 | E40: 20411 | F40: 8791 | G40: =VLOOKUP(B40,'Kings Ratings'!$A$2:$B$1000,2,false) -> 2 | H40: =if(G40=11,13,13-ROUNDDOWN(log(J40,4),0)) -> 0 | I40: =vlookup(A40,'202405 MM (Do Not Delete)'!$A$1:$G$1000,7,false) -> 222 | J40: =10000*F40+10*E40+D40 -> 88151554 | L40: =IFERROR(__xludf.DUMMYFUNCTION("if(REGEXMATCH(vlookup(B40,'Kings Ratings'!$A$2:$C$1000,3,false),""Fishing""),""Yes"","""")"),"") | M40: =IFERROR(__xludf.DUMMYFUNCTION("if(REGEXMATCH(vlookup(B40,'Kings Ratings'!$A$2:$C$1000,3,false),""Crafting""),""Yes"","""")"),"") | N40: =IFERROR(__xludf.DUMMYFUNCTION("if(REGEXMATCH(vlookup(B40,'Kings Ratings'!$A$2:$C$1000,3,false),""Exploring""),""Yes"","""")"),"") | O40: =IFERROR(__xludf.DUMMYFUNCTION("if(REGEXMATCH(vlookup(B40,'Kings Ratings'!$A$2:$C$1000,3,false),""Farming""),""Yes"","""")"),"") | P40: =IFERROR(__xludf.DUMMYFUNCTION("if(REGEXMATCH(vlookup(B40,'Kings Ratings'!$A$2:$C$1000,3,false),""Cooking""),""Yes"","""")"),"") | Q40: =IFERROR(__xludf.DUMMYFUNCTION("if(REGEXMATCH(vlookup(B40,'Kings Ratings'!$A$2:$C$1000,3,false),""Event""),""Yes"","""")"),"")
...

Sheet Ignore -->
A2: Totals
A4: Date | B4: M | C4: GM | D4: MM | F4: days since last | G4: Daily inc M | H4: Daily Inc GM | I4: Daily Inc MM | Q4: Date | R4: M | S4: GM | T4: MM
A5: 46169 | B5: 6649613 | C5: 3126043 | D5: 1141625 | F5: =A5-A6 -> 80 | G5: =(B5-B6)/$F5 -> 4979.625 | H5: =(C5-C6)/$F5 -> 2663.05 | I5: =(D5-D6)/$F5 -> 1280.5375 | Q5: =A5 -> 46169 | R5: =B5/$B$19 -> 2.1657586 | S5: =C5/$C$19 -> 2.3188888 | T5: =D5/$D$19 -> 3.5054118
A6: 46089 | B6: =sum('Export 260308'!C2:C492) -> 6251243 | C6: =sum('Export 260308'!D2:D492) -> 2912999 | D6: =sum('Export 260308'!E2:E492) -> 1039182 | F6: =A6-A7 -> 104 | G6: =(B6-B7)/$F6 -> 5296.9904 | H6: =(C6-C7)/$F6 -> 2495.1538 | I6: =(D6-D7)/$F6 -> 1188.375 | Q6: =A6 -> 46089 | R6: =B6/$B$19 -> 2.0360107 | S6: =C6/$C$19 -> 2.1608535 | T6: =D6/$D$19 -> 3.1908559
A7: 45985 | B7: 5700356 | C7: 2653503 | D7: 915591 | F7: =A7-A8 -> 102 | G7: =(B7-B8)/$F7 -> 3826.0882 | H7: =(C7-C8)/$F7 -> 1948.1078 | I7: =(D7-D8)/$F7 -> 1041.4118 | Q7: =A7 -> 45985 | R7: =B7/$B$19 -> 1.8565885 | S7: =C7/$C$19 -> 1.9683601 | T7: =D7/$D$19 -> 2.8113641
A8: 45883 | B8: 5310095 | C8: 2454796 | D8: 809367 | F8: =A8-A9 -> 43 | G8: =(B8-B9)/$F8 -> 3950.2326 | H8: =(C8-C9)/$F8 -> 2111.5349 | I8: =(D8-D9)/$F8 -> 1240.5116 | Q8: =A8 -> 45883 | R8: =B8/$B$19 -> 1.7294817 | S8: =C8/$C$19 -> 1.8209599 | T8: =D8/$D$19 -> 2.4851984
A9: 45840 | B9: 5140235 | C9: 2364000 | D9: 756025 | F9: =A9-A10 -> 38 | G9: =(B9-B10)/$F9 -> 4298.0526 | H9: =(C9-C10)/$F9 -> 2303.1579 | I9: =(D9-D10)/$F9 -> 1158.7632 | Q9: =A9 -> 45840 | R9: =B9/$B$19 -> 1.6741588 | S9: =C9/$C$19 -> 1.7536077 | T9: =D9/$D$19 -> 2.3214094
A10: 45802 | B10: 4976909 | C10: 2276480 | D10: 711992 | F10: =A10-A11 -> 41 | G10: =(B10-B11)/$F10 -> 5240.0488 | H10: =(C10-C11)/$F10 -> 2680.4634 | I10: =(D10-D11)/$F10 -> 1204.0488 | Q10: =A10 -> 45802 | R10: =B10/$B$19 -> 1.620964 | S10: =C10/$C$19 -> 1.6886857 | T10: =D10/$D$19 -> 2.186204
A11: 45761 | B11: 4762067 | C11: 2166581 | D11: 662626 | F11: =A11-A12 -> 72 | G11: =(B11-B12)/$F11 -> 4649.8889 | H11: =(C11-C12)/$F11 -> 2284.3333 | I11: =(D11-D12)/$F11 -> 1029.9306 | Q11: =A11 -> 45761 | R11: =B11/$B$19 -> 1.5509906 | S11: =C11/$C$19 -> 1.6071629 | T11: =D11/$D$19 -> 2.0346235
A12: 45689 | B12: 4427275 | C12: 2002109 | D12: 588471 | F12: =A12-A13 -> 30 | G12: =(B12-B13)/$F12 -> 4955.2667 | H12: =(C12-C13)/$F12 -> 2587.0667 | I12: =(D12-D13)/$F12 -> 1202.6667 | Q12: =A12 -> 45689 | R12: =B12/$B$19 -> 1.4419499 | S12: =C12/$C$19 -> 1.4851581 | T12: =D12/$D$19 -> 1.8069272
A13: 45659 | B13: 4278617 | C13: 1924497 | D13: 552391 | F13: =A13-A14 -> 31 | G13: =(B13-B14)/$F13 -> 7213.6129 | H13: =(C13-C14)/$F13 -> 3241.7742 | I13: =(D13-D14)/$F13 -> 1227.4194 | Q13: =A13 -> 45659 | R13: =B13/$B$19 -> 1.3935324 | S13: =C13/$C$19 -> 1.4275858 | T13: =D13/$D$19 -> 1.6961419
A14: 45628 | B14: 4054995 | C14: 1824002 | D14: 514341 | F14: =A14-A15 -> 31 | G14: =(B14-B15)/$F14 -> 4921.5161 | H14: =(C14-C15)/$F14 -> 2340 | I14: =(D14-D15)/$F14 -> 993.09677 | Q14: =A14 -> 45628 | R14: =B14/$B$19 -> 1.3206994 | S14: =C14/$C$19 -> 1.3530389 | T14: =D14/$D$19 -> 1.5793076
A15: 45597 | B15: 3902428 | C15: 1751462 | D15: 483555 | F15: =A15-A16 -> 31 | G15: =(B15-B16)/$F15 -> 5272.4516 | H15: =(C15-C16)/$F15 -> 2543.4839 | I15: =(D15-D16)/$F15 -> 1040.9355 | Q15: =A15 -> 45597 | R15: =B15/$B$19 -> 1.2710088 | S15: =C15/$C$19 -> 1.299229 | T15: =D15/$D$19 -> 1.4847778
A16: 45566 | B16: 3738982 | C16: 1672614 | D16: 451286 | F16: =A16-A17 -> 50 | G16: =(B16-B17)/$F16 -> 4805.26 | H16: =(C16-C17)/$F16 -> 2448.1 | I16: =(D16-D17)/$F16 -> 1019.3 | Q16: =A16 -> 45566 | R16: =B16/$B$19 -> 1.217775 | S16: =C16/$C$19 -> 1.2407398 | T16: =D16/$D$19 -> 1.3856943
A17: 45516 | B17: 3498719 | C17: 1550209 | D17: 400321 | F17: =A17-A18 -> 40 | G17: =(B17-B18)/$F17 -> 4668.375 | H17: =(C17-C18)/$F17 -> 2350.325 | I17: =(D17-D18)/$F17 -> 875.85 | Q17: =A17 -> 45516 | R17: =B17/$B$19 -> 1.1395221 | S17: =C17/$C$19 -> 1.1499401 | T17: =D17/$D$19 -> 1.229204
A18: 45476 | B18: 3311984 | C18: 1456196 | D18: 365287 | F18: =A18-A19 -> 41 | G18: =(B18-B19)/$F18 -> 5893.7805 | H18: =(C18-C19)/$F18 -> 2637.0244 | I18: =(D18-D19)/$F18 -> 966.14634 | Q18: =A18 -> 45476 | R18: =B18/$B$19 -> 1.078703 | S18: =C18/$C$19 -> 1.0802016 | T18: =D18/$D$19 -> 1.1216305
A19: 45435 | B19: 3070339 | C19: 1348078 | D19: 325675 | Q19: =A19 -> 45435 | R19: =B19/$B$19 -> 1 | S19: =C19/$C$19 -> 1 | T19: =D19/$D$19 -> 1

Sheet Kings Ratings
A1: Item | B1: Difficulty Rating | C1: Best Method | D1: Notes
A2: Acorn Butter | B2: 10 | C2: Crafting | D2: Good way to use up , but it needs so many that GM will take a long long time. Always make sure you're tossing them here instead of voiding though.
A3: Amber Cane | B3: 10 | C3: Crafting | D3: Requires , which is a Super Rare, and costly to explore for. You get it from your Lemur at level 6, but not enough to go for GM, or even mastery really.
A4: Amethyst Necklace | B4: 2 | C4: Crafting | D4: Quick to gm, or MM, while working on other Highland Hills masteries. Can also get from opening , 5 each.
A5: Apple Cider | B5: 8 | C5: Crafting, Quests | D5: Fairly easy to master, but GM will take some time. You also get a good amount from quests and some from pets over time. If you care about GM, use when claiming large amounts from quests.
A6: Aquamarine Ring | B6: 3 | C6: Crafting | D6: Needs paste, but pretty cheap and quick overall. Not much else to do in Small Spring though while collecting , so try to make the most of the you get while working on this. Can also get from opening , 5 each.
A7: Arnold Palmer | B7: 8 | C7: Crafting, Quests | D7: You will always want to turn your lemonade into AP, but this will probably take a long time to GM. If you care about GM on this, make sure you're using for quests that reward more than a few hundred.
A8: Awl | B8: 1 | C8: Crafting | D8: Very cheap and simple. Can be done entirely passively.
A9: Axe | B9: 2 | C9: Crafting | D9: Very easy GM or MM, able to be worked on at any point in the game. It's best to use your axes for Exchange Center trades, or send to Vincent for friendship XP. You can also explore Small Cave and turn these directly into as well, provided you can keep up production.
A10: Barracuda | B10: 1 | C10: Fishing | D10: Very very low effort, just use and in Large Island. Make sure to sell these for silver.
A11: Beet | B11: 5 | C11: Farming | D11: You should only really work on this with and ; either from your Strange Onion pet, or the Exchange Center. Make sure to use and it will be pretty quick. Sell, don't void, since they're worth a lot.
A12: Belt Drive | B12: 7 | C12: Crafting | D12: You will definitely want to be working on these when exploring Jundland Desert. If possible, use them to make , but those can be quite costly so in my opinion it's fine to sell extras if you can't.
A13: Black Powder | B13: 2 | C13: Crafting | D13: Can be done actively via exploring, or passively via Quarry. Either use it for , , or Beatrix friendship XP.
A14: Block of Wood | B14: 10 | C14: Crafting
A15: Blue Catfish | B15: 3 | C15: Fishing | D15: One of the slower Crystal River masteries, but still quite easy... just spam nets.
A16: Blue Crab | B16: 2 | C16: Fishing | D16: There are lots of fish to master at Small Island and this is one of the quicker ones. Send these to Captain Thomas or Geist for friendship xp.
A17: Blue Diary | B17: 2 | C17: Crafting | D17: Fairly simple, but useless.
A18: Blue Dye | B18: 3 | C18: Crafting | D18: One of the main reasons to explore Misty Forest. You should turn these into so you can make a lot of silver. If you don't have those unlocked yet, or have already finished, you can knock out ((Fancy Pan Flutes)) pretty wuickly, if you can keep up with the needed.
A19: Blue Parchment | B19: 2 | C19: Crafting | D19: Less use than , but slightly cheaper. Turn it into diaries.
A20: Blue Purse | B20: 4 | C20: Crafting | D20: Work on this while doing and to make some easy silver.
A21: Blue Sea Bass | B21: 2 | C21: Fishing | D21: Drops from Small Island or Vast Ocean. The rates are pretty low from both, but you should make good progress while GMing the easiesr fish in each zone.
A22: Blue Shell | B22: 3 | C22: Fishing | D22: Medium difficulty Small Island fish, just keep throwing nets at the zone.
A23: Blue Tiger Fish | B23: 2 | C23: Fishing | D23: One of the slower Emerald Beach Fish, but not the slowest.
A24: Blue Twine | B24: 3 | C24: Crafting | D24: Throw some on twine and call it a day.
A25: Bluegill | B25: 2 | C25: Fishing | D25: Forest Pond is a great fishing zone for friendship xp, and a few quick fishing GMs. Send these to Holger.
A26: Board | B26: 1 | C26: Crafting, Sawmill | D26: Boards are most people's first mastery and GM. Upgrading your sawmill is essential for Sawmill Silver and many masteries. Check out kings page for lots of craftworks ideas for how to use these entirely passively.
... A39: Cabbage Stew | B39: 10 | C39: Cooking | D39: Very high resource cost (it's mostly , which take forever to grow).
A40: Candy Corn | B40: 11
A41: Cannon | B41: 10 | C41: Crafting
A42: Canoe | B42: 9 | C42: Crafting | D42: The amount of needed for these is insane. They also need a good amount of which can get annoying fast. Most people that have GMed these just did it because they were bored, genuinely. Plus side is, you'll get loads of while working on it.
A43: Carp | B43: 3 | C43: Fishing | D43: Most people overlook this fish, even though it's pretty easy. That's likely because the other easy Farm Pond fish also come from other locations, and they normally get GMed from those. Send these to Holger or Thomas.
A44: Carrot | B44: 3 | C44: Farming | D44: Don't work on this GM until you have access to , whether by cooking it yourself, or trading. It's rather painless with the meal, just a bunch of clicking. Send your spares to frank, or Rosalie/Charles Horsington III.
A45: Cat's Meow | B45: 9 | C45: Cooking | D45: Lower-cook time meal, which means tasting gives less mastery, but relatively cheap. Gm will take a long time.
A46: Catfish | B46: 5 | C46: Fishing, Locksmith | D46: Catfish have a pretty low drop rate from fishing in the Farm Pond. Luckily you can also get them from opening , which you get from fishing in the Forest Pond. So don't stress.
A47: Christmas Tree | B47: 11
A48: Chum | B48: 3 | C48: Crafting | D48: Can be worked on entirely from passive production. Make sure you upgrade your Trout/Bait Farm and Worm Habitat to keep production flowing. These sell for decent silver as well.
A49: Clam Shell | B49: 1 | C49: Fishing | D49: Very easy Emerald Beach fishing mastery.
A50: Clownfish | B50: 2 | C50: Fishing | D50: Fairly quick Emerald Beach mastery.
A51: Coin Purse | B51: 5 | C51: Crafting | D51: Make sure you turn these into as much as possible, because the silver is really good.
A52: Compass | B52: 10 | C52: Crafting | D52: The only way to craft is to toss them into the Wishing Well, then recraft with the you get back. It's very expensive, as each costs 4x and your free tosses into the well are limited. It's is somewhat reasonable (although expensive) to master over a long period of time. GM is out of the question.
...

Sheet Export 260901
A1: Item | B1: ItemID | C1: Mastered | D1: Grand Mastered | E1: Mega Mastered | F1: Progress | H1: King's Rating April 2023* | I1: Tower Req | K1: Mastered | L1: M Change | M1: % Change | P1: Grand Mastered | Q1: GM Change | R1: % Change | U1: Mega Mastered | V1: MM Change | W1: % Change
A2: Lobster | B2: 1155 | C2: 0 | D2: 0 | E2: 0 | F2: 1 | H2: =VLOOKUP(A2,'Kings Ratings'!$A$2:$B$1000,2,false) -> 11 | K2: 0 | L2: =C2-K2 -> 0 | M2: =L2/K2 -> #DIV/0! | N2: =CONCATENATE(A2, " with +",L2, ", +", 100*round(M2,3), "% (",K2, " to ",C2,")") -> #DIV/0! | P2: 0 | Q2: =D2-P2 -> 0 | R2: =Q2/P2 -> #DIV/0! | S2: =CONCATENATE(A2, " with +",Q2, ", +", 100*round(R2,3), "% (",P2, " to ",D2,")") -> #DIV/0! | U2: 0 | V2: =E2-U2 -> 0 | W2: =V2/U2 -> #DIV/0! | X2: =CONCATENATE(A2, " with +",V2, ", +", 100*round(W2,3), "% (",U2, " to ",E2,")") -> #DIV/0!
A3: Sea Urchin | B3: 1241 | C3: 0 | D3: 0 | E3: 0 | F3: 882 | H3: =VLOOKUP(A3,'Kings Ratings'!$A$2:$B$1000,2,false) -> 10 | K3: 0 | L3: =C3-K3 -> 0 | M3: =L3/K3 -> #DIV/0! | N3: =CONCATENATE(A3, " with +",L3, ", +", 100*round(M3,3), "% (",K3, " to ",C3,")") -> #DIV/0! | P3: 0 | Q3: =D3-P3 -> 0 | R3: =Q3/P3 -> #DIV/0! | S3: =CONCATENATE(A3, " with +",Q3, ", +", 100*round(R3,3), "% (",P3, " to ",D3,")") -> #DIV/0! | U3: 0 | V3: =E3-U3 -> 0 | W3: =V3/U3 -> #DIV/0! | X3: =CONCATENATE(A3, " with +",V3, ", +", 100*round(W3,3), "% (",U3, " to ",E3,")") -> #DIV/0!
A4: Ghost Jelly | B4: 1242 | C4: 0 | D4: 0 | E4: 0 | F4: 927 | H4: =VLOOKUP(A4,'Kings Ratings'!$A$2:$B$1000,2,false) -> 10 | K4: 0 | L4: =C4-K4 -> 0 | M4: =L4/K4 -> #DIV/0! | N4: =CONCATENATE(A4, " with +",L4, ", +", 100*round(M4,3), "% (",K4, " to ",C4,")") -> #DIV/0! | P4: 0 | Q4: =D4-P4 -> 0 | R4: =Q4/P4 -> #DIV/0! | S4: =CONCATENATE(A4, " with +",Q4, ", +", 100*round(R4,3), "% (",P4, " to ",D4,")") -> #DIV/0! | U4: 0 | V4: =E4-U4 -> 0 | W4: =V4/U4 -> #DIV/0! | X4: =CONCATENATE(A4, " with +",V4, ", +", 100*round(W4,3), "% (",U4, " to ",E4,")") -> #DIV/0!
